import createError from "../utils/createError.js";
import Order from "../models/order.model.js";
import Gig from "../models/gig.model.js";

export const createOrder = async (req, res, next) => {
  try {
    const gig = await Gig.findById(req.params.id);

    if (!gig) {
      return next(createError(404, "Gig not found"));
    }

    const newOrder = new Order({
      gigId: gig._id,
      img: gig.cover,
      title: gig.title,
      buyerId: req.userId,
      sellerId: gig.userId,
      price: gig.price,
    });

    await newOrder.save();
    res.status(200).send("Order created successfully");
  } catch (err) {
    next(err);
  }
};

export const getOrders = async (req, res, next) => {
  try {
    const orders = await Order.find({
      ...(req.isSeller ? { sellerId: req.userId } : { buyerId: req.userId }),
      isCompleted: true,
    });

    res.status(200).send(orders);
  } catch (err) {
    next(err);
  }
};
export const confirm = async (req, res, next) => {
  try {
    const order = await Order.findByIdAndUpdate(
      req.params.id,
      {
        $set: {
          isCompleted: true,
        },
      },
      { new: true }
    );

    if (!order) {
      return next(createError(404, "Order not found"));
    }

    res.status(200).send("Order has been confirmed.");
  } catch (err) {
    next(err);
  }
};
